2024-04-14 10:54:44,103 ERROR: Exception on /auth/login [GET] [in D:\microblog\venv\lib\site-packages\flask\app.py:828]
Traceback (most recent call last):
  File "D:\microblog\venv\lib\site-packages\flask\app.py", line 1463, in wsgi_app
    response = self.full_dispatch_request()
  File "D:\microblog\venv\lib\site-packages\flask\app.py", line 872, in full_dispatch_request
    rv = self.handle_user_exception(e)
  File "D:\microblog\venv\lib\site-packages\flask\app.py", line 870, in full_dispatch_request
    rv = self.dispatch_request()
  File "D:\microblog\venv\lib\site-packages\flask\app.py", line 855, in dispatch_request
    return self.ensure_sync(self.view_functions[rule.endpoint])(**view_args)  # type: ignore[no-any-return]
  File "D:\microblog\app\auth\routes.py", line 31, in login
    return render_template('auth/login.html',title='Sign in',form=form)
  File "D:\microblog\venv\lib\site-packages\flask\templating.py", line 150, in render_template
    return _render(app, template, context)
  File "D:\microblog\venv\lib\site-packages\flask\templating.py", line 131, in _render
    rv = template.render(context)
  File "D:\microblog\venv\lib\site-packages\jinja2\environment.py", line 1301, in render
    self.environment.handle_exception()
  File "D:\microblog\venv\lib\site-packages\jinja2\environment.py", line 936, in handle_exception
    raise rewrite_traceback_stack(source=source)
  File "D:\microblog\app\templates\auth\login.html", line 1, in top-level template code
    {% extends 'base.html' %} {% import "bootstrap_wtf.html" as wtf %} {% block
  File "D:\microblog\app\templates\base.html", line 21, in top-level template code
    <a class="navbar-brand" href="{{ url_for('index') }}">Microblog</a>
  File "D:\microblog\venv\lib\site-packages\flask\app.py", line 1074, in url_for
    return self.handle_url_build_error(error, endpoint, values)
  File "D:\microblog\venv\lib\site-packages\flask\app.py", line 1063, in url_for
    rv = url_adapter.build(  # type: ignore[union-attr]
  File "D:\microblog\venv\lib\site-packages\werkzeug\routing\map.py", line 919, in build
    raise BuildError(endpoint, values, method, self)
werkzeug.routing.exceptions.BuildError: Could not build url for endpoint 'index'. Did you mean 'main.index' instead?
2024-04-14 10:55:32,971 INFO: Microblog startup [in D:\microblog\app\__init__.py:69]
2024-04-14 10:55:38,795 ERROR: Exception on /auth/login [GET] [in D:\microblog\venv\lib\site-packages\flask\app.py:828]
Traceback (most recent call last):
  File "D:\microblog\venv\lib\site-packages\flask\app.py", line 1463, in wsgi_app
    response = self.full_dispatch_request()
  File "D:\microblog\venv\lib\site-packages\flask\app.py", line 872, in full_dispatch_request
    rv = self.handle_user_exception(e)
  File "D:\microblog\venv\lib\site-packages\flask\app.py", line 870, in full_dispatch_request
    rv = self.dispatch_request()
  File "D:\microblog\venv\lib\site-packages\flask\app.py", line 855, in dispatch_request
    return self.ensure_sync(self.view_functions[rule.endpoint])(**view_args)  # type: ignore[no-any-return]
  File "D:\microblog\app\auth\routes.py", line 31, in login
    return render_template('auth/login.html',title='Sign in',form=form)
  File "D:\microblog\venv\lib\site-packages\flask\templating.py", line 150, in render_template
    return _render(app, template, context)
  File "D:\microblog\venv\lib\site-packages\flask\templating.py", line 131, in _render
    rv = template.render(context)
  File "D:\microblog\venv\lib\site-packages\jinja2\environment.py", line 1301, in render
    self.environment.handle_exception()
  File "D:\microblog\venv\lib\site-packages\jinja2\environment.py", line 936, in handle_exception
    raise rewrite_traceback_stack(source=source)
  File "D:\microblog\app\templates\auth\login.html", line 1, in top-level template code
    {% extends 'base.html' %} {% import "bootstrap_wtf.html" as wtf %} {% block
  File "D:\microblog\app\templates\base.html", line 21, in top-level template code
    <a class="navbar-brand" href="{{ url_for('index') }}">Microblog</a>
  File "D:\microblog\venv\lib\site-packages\flask\app.py", line 1074, in url_for
    return self.handle_url_build_error(error, endpoint, values)
  File "D:\microblog\venv\lib\site-packages\flask\app.py", line 1063, in url_for
    rv = url_adapter.build(  # type: ignore[union-attr]
  File "D:\microblog\venv\lib\site-packages\werkzeug\routing\map.py", line 919, in build
    raise BuildError(endpoint, values, method, self)
werkzeug.routing.exceptions.BuildError: Could not build url for endpoint 'index'. Did you mean 'main.index' instead?
2024-04-14 10:57:32,191 INFO: Microblog startup [in D:\microblog\app\__init__.py:69]
2024-04-14 10:58:08,606 ERROR: Exception on /auth/login [GET] [in D:\microblog\venv\lib\site-packages\flask\app.py:828]
Traceback (most recent call last):
  File "D:\microblog\venv\lib\site-packages\flask\app.py", line 1463, in wsgi_app
    response = self.full_dispatch_request()
  File "D:\microblog\venv\lib\site-packages\flask\app.py", line 872, in full_dispatch_request
    rv = self.handle_user_exception(e)
  File "D:\microblog\venv\lib\site-packages\flask\app.py", line 870, in full_dispatch_request
    rv = self.dispatch_request()
  File "D:\microblog\venv\lib\site-packages\flask\app.py", line 855, in dispatch_request
    return self.ensure_sync(self.view_functions[rule.endpoint])(**view_args)  # type: ignore[no-any-return]
  File "D:\microblog\app\auth\routes.py", line 31, in login
    return render_template('auth/login.html',title='Sign in',form=form)
  File "D:\microblog\venv\lib\site-packages\flask\templating.py", line 150, in render_template
    return _render(app, template, context)
  File "D:\microblog\venv\lib\site-packages\flask\templating.py", line 131, in _render
    rv = template.render(context)
  File "D:\microblog\venv\lib\site-packages\jinja2\environment.py", line 1301, in render
    self.environment.handle_exception()
  File "D:\microblog\venv\lib\site-packages\jinja2\environment.py", line 936, in handle_exception
    raise rewrite_traceback_stack(source=source)
  File "D:\microblog\app\templates\auth\login.html", line 1, in top-level template code
    {% extends 'base.html' %} {% import "bootstrap_wtf.html" as wtf %} {% block
  File "D:\microblog\app\templates\base.html", line 21, in top-level template code
    <a class="navbar-brand" href="{{ url_for('index') }}">Microblog</a>
  File "D:\microblog\venv\lib\site-packages\flask\app.py", line 1074, in url_for
    return self.handle_url_build_error(error, endpoint, values)
  File "D:\microblog\venv\lib\site-packages\flask\app.py", line 1063, in url_for
    rv = url_adapter.build(  # type: ignore[union-attr]
  File "D:\microblog\venv\lib\site-packages\werkzeug\routing\map.py", line 919, in build
    raise BuildError(endpoint, values, method, self)
werkzeug.routing.exceptions.BuildError: Could not build url for endpoint 'index'. Did you mean 'main.index' instead?
2024-04-14 11:00:19,321 INFO: Microblog startup [in D:\microblog\app\__init__.py:69]
2024-04-14 11:00:30,772 ERROR: Exception on / [GET] [in D:\microblog\venv\lib\site-packages\flask\app.py:828]
Traceback (most recent call last):
  File "D:\microblog\venv\lib\site-packages\flask\app.py", line 1463, in wsgi_app
    response = self.full_dispatch_request()
  File "D:\microblog\venv\lib\site-packages\flask\app.py", line 872, in full_dispatch_request
    rv = self.handle_user_exception(e)
  File "D:\microblog\venv\lib\site-packages\flask\app.py", line 870, in full_dispatch_request
    rv = self.dispatch_request()
  File "D:\microblog\venv\lib\site-packages\flask\app.py", line 855, in dispatch_request
    return self.ensure_sync(self.view_functions[rule.endpoint])(**view_args)  # type: ignore[no-any-return]
  File "D:\microblog\venv\lib\site-packages\flask_login\utils.py", line 290, in decorated_view
    return current_app.ensure_sync(func)(*args, **kwargs)
  File "D:\microblog\app\main\routes.py", line 33, in index
    return render_template('index.html',title='home',posts=posts.items,form=form,next_url=next_url,prev_url=prev_url)
  File "D:\microblog\venv\lib\site-packages\flask\templating.py", line 150, in render_template
    return _render(app, template, context)
  File "D:\microblog\venv\lib\site-packages\flask\templating.py", line 131, in _render
    rv = template.render(context)
  File "D:\microblog\venv\lib\site-packages\jinja2\environment.py", line 1301, in render
    self.environment.handle_exception()
  File "D:\microblog\venv\lib\site-packages\jinja2\environment.py", line 936, in handle_exception
    raise rewrite_traceback_stack(source=source)
  File "D:\microblog\app\templates\index.html", line 2, in top-level template code
    {% import "bootstrap_wtf.html" as wtf %}
  File "D:\microblog\app\templates\base.html", line 88, in top-level template code
    {% endfor %} {% endif %} {% endwith %} {% block content %}{% endblock %}
  File "D:\microblog\app\templates\index.html", line 10, in block 'content'
    {% include '_post.html' %}
  File "D:\microblog\app\templates\_post.html", line 4, in top-level template code
    <a href="{{ url_for('user', username=post.author.username) }}">
  File "D:\microblog\venv\lib\site-packages\flask\app.py", line 1074, in url_for
    return self.handle_url_build_error(error, endpoint, values)
  File "D:\microblog\venv\lib\site-packages\flask\app.py", line 1063, in url_for
    rv = url_adapter.build(  # type: ignore[union-attr]
  File "D:\microblog\venv\lib\site-packages\werkzeug\routing\map.py", line 919, in build
    raise BuildError(endpoint, values, method, self)
werkzeug.routing.exceptions.BuildError: Could not build url for endpoint 'user' with values ['username']. Did you mean 'main.user' instead?
2024-04-14 11:01:51,322 INFO: Microblog startup [in D:\microblog\app\__init__.py:69]
2024-04-15 17:41:06,308 INFO: Microblog startup [in D:\microblog\app\__init__.py:69]
