2024-04-11 11:29:35,288 ERROR: Exception on /user/Vadiraj [GET] [in D:\microblog\venv\lib\site-packages\flask\app.py:828]
Traceback (most recent call last):
  File "D:\microblog\venv\lib\site-packages\flask\app.py", line 1463, in wsgi_app
    response = self.full_dispatch_request()
  File "D:\microblog\venv\lib\site-packages\flask\app.py", line 872, in full_dispatch_request
    rv = self.handle_user_exception(e)
  File "D:\microblog\venv\lib\site-packages\flask\app.py", line 870, in full_dispatch_request
    rv = self.dispatch_request()
  File "D:\microblog\venv\lib\site-packages\flask\app.py", line 855, in dispatch_request
    return self.ensure_sync(self.view_functions[rule.endpoint])(**view_args)  # type: ignore[no-any-return]
  File "D:\microblog\venv\lib\site-packages\flask_login\utils.py", line 290, in decorated_view
    return current_app.ensure_sync(func)(*args, **kwargs)
  File "D:\microblog\app\routes.py", line 72, in user
    return render_template('user.html',user=user,posts=posts,form=form,next_url=next_url,prev_url=prev_url)
  File "D:\microblog\venv\lib\site-packages\flask\templating.py", line 150, in render_template
    return _render(app, template, context)
  File "D:\microblog\venv\lib\site-packages\flask\templating.py", line 131, in _render
    rv = template.render(context)
  File "D:\microblog\venv\lib\site-packages\jinja2\environment.py", line 1301, in render
    self.environment.handle_exception()
  File "D:\microblog\venv\lib\site-packages\jinja2\environment.py", line 936, in handle_exception
    raise rewrite_traceback_stack(source=source)
  File "D:\microblog\app\templates\user.html", line 1, in top-level template code
    {% extends "base.html" %}
  File "D:\microblog\app\templates\base.html", line 58, in top-level template code
    {% block content %}{% endblock %}
  File "D:\microblog\app\templates\user.html", line 11, in block 'content'
    <p>{{ user.followers.count() }} followers, {{ user.followed.count() }} following.</p>
  File "D:\microblog\venv\lib\site-packages\jinja2\utils.py", line 83, in from_obj
    if hasattr(obj, "jinja_pass_arg"):
jinja2.exceptions.UndefinedError: 'app.models.User object' has no attribute 'following_count'
2024-04-11 11:29:41,655 INFO: Microblog startup [in D:\microblog\app\__init__.py:48]
2024-04-11 11:58:58,274 INFO: Microblog startup [in D:\microblog\app\__init__.py:52]
2024-04-11 12:02:14,943 INFO: Microblog startup [in D:\microblog\app\__init__.py:54]
2024-04-11 12:02:41,005 INFO: Microblog startup [in D:\microblog\app\__init__.py:54]
2024-04-11 12:39:30,054 INFO: Microblog startup [in D:\microblog\app\__init__.py:54]
2024-04-11 12:40:53,478 INFO: Microblog startup [in D:\microblog\app\__init__.py:54]
2024-04-11 12:41:27,748 INFO: Microblog startup [in D:\microblog\app\__init__.py:54]
2024-04-11 12:42:44,120 INFO: Microblog startup [in D:\microblog\app\__init__.py:54]
2024-04-11 12:43:59,131 INFO: Microblog startup [in D:\microblog\app\__init__.py:54]
2024-04-11 12:45:33,557 INFO: Microblog startup [in D:\microblog\app\__init__.py:54]
2024-04-11 12:46:07,333 INFO: Microblog startup [in D:\microblog\app\__init__.py:54]
2024-04-11 12:47:29,133 INFO: Microblog startup [in D:\microblog\app\__init__.py:54]
2024-04-11 12:47:52,610 INFO: Microblog startup [in D:\microblog\app\__init__.py:54]
2024-04-11 12:48:33,897 INFO: Microblog startup [in D:\microblog\app\__init__.py:54]
2024-04-11 12:50:20,187 INFO: Microblog startup [in D:\microblog\app\__init__.py:54]
2024-04-11 12:50:23,731 ERROR: Exception on /user/Vadiraj [GET] [in D:\microblog\venv\lib\site-packages\flask\app.py:828]
Traceback (most recent call last):
  File "D:\microblog\venv\lib\site-packages\flask\app.py", line 1463, in wsgi_app
    response = self.full_dispatch_request()
  File "D:\microblog\venv\lib\site-packages\flask\app.py", line 872, in full_dispatch_request
    rv = self.handle_user_exception(e)
  File "D:\microblog\venv\lib\site-packages\flask\app.py", line 870, in full_dispatch_request
    rv = self.dispatch_request()
  File "D:\microblog\venv\lib\site-packages\flask\app.py", line 855, in dispatch_request
    return self.ensure_sync(self.view_functions[rule.endpoint])(**view_args)  # type: ignore[no-any-return]
  File "D:\microblog\venv\lib\site-packages\flask_login\utils.py", line 290, in decorated_view
    return current_app.ensure_sync(func)(*args, **kwargs)
  File "D:\microblog\app\routes.py", line 73, in user
    return render_template('user.html',user=user,posts=posts,form=form,next_url=next_url,prev_url=prev_url)
  File "D:\microblog\venv\lib\site-packages\flask\templating.py", line 150, in render_template
    return _render(app, template, context)
  File "D:\microblog\venv\lib\site-packages\flask\templating.py", line 131, in _render
    rv = template.render(context)
  File "D:\microblog\venv\lib\site-packages\jinja2\environment.py", line 1301, in render
    self.environment.handle_exception()
  File "D:\microblog\venv\lib\site-packages\jinja2\environment.py", line 936, in handle_exception
    raise rewrite_traceback_stack(source=source)
  File "D:\microblog\app\templates\user.html", line 1, in top-level template code
    {% extends "base.html" %}
  File "D:\microblog\app\templates\base.html", line 65, in top-level template code
    {% block scripts %}
  File "D:\microblog\app\templates\base.html", line 66, in block 'scripts'
    {{ super() }}
  File "D:\microblog\venv\lib\site-packages\jinja2\utils.py", line 83, in from_obj
    if hasattr(obj, "jinja_pass_arg"):
jinja2.exceptions.UndefinedError: there is no parent block called 'scripts'.
2024-04-11 12:50:46,100 INFO: Microblog startup [in D:\microblog\app\__init__.py:54]
2024-04-11 13:15:40,350 INFO: Microblog startup [in D:\microblog\app\__init__.py:54]
2024-04-11 13:17:01,750 INFO: Microblog startup [in D:\microblog\app\__init__.py:54]
2024-04-11 13:17:25,182 INFO: Microblog startup [in D:\microblog\app\__init__.py:54]
2024-04-11 13:17:38,363 INFO: Microblog startup [in D:\microblog\app\__init__.py:54]
2024-04-11 18:46:04,649 INFO: Microblog startup [in D:\microblog\app\__init__.py:54]
2024-04-11 18:46:14,541 INFO: Microblog startup [in D:\microblog\app\__init__.py:54]
2024-04-13 10:28:57,887 INFO: Microblog startup [in D:\microblog\app\__init__.py:54]
2024-04-13 10:32:35,700 INFO: Microblog startup [in D:\microblog\app\__init__.py:54]
2024-04-13 10:33:00,239 INFO: Microblog startup [in D:\microblog\app\__init__.py:54]
2024-04-13 10:33:09,346 ERROR: Exception on /favicon.ico [GET] [in D:\microblog\venv\lib\site-packages\flask\app.py:828]
Traceback (most recent call last):
  File "D:\microblog\venv\lib\site-packages\flask\app.py", line 870, in full_dispatch_request
    rv = self.dispatch_request()
  File "D:\microblog\venv\lib\site-packages\flask\app.py", line 844, in dispatch_request
    self.raise_routing_exception(req)
  File "D:\microblog\venv\lib\site-packages\flask\app.py", line 453, in raise_routing_exception
    raise request.routing_exception  # type: ignore[misc]
  File "D:\microblog\venv\lib\site-packages\flask\ctx.py", line 362, in match_request
    result = self.url_adapter.match(return_rule=True)  # type: ignore
  File "D:\microblog\venv\lib\site-packages\werkzeug\routing\map.py", line 624, in match
    raise NotFound() from None
werkzeug.exceptions.NotFound: 404 Not Found: The requested URL was not found on the server. If you entered the URL manually please check your spelling and try again.

During handling of the above exception, another exception occurred:

Traceback (most recent call last):
  File "D:\microblog\venv\lib\site-packages\flask\app.py", line 1463, in wsgi_app
    response = self.full_dispatch_request()
  File "D:\microblog\venv\lib\site-packages\flask\app.py", line 872, in full_dispatch_request
    rv = self.handle_user_exception(e)
  File "D:\microblog\venv\lib\site-packages\flask\app.py", line 755, in handle_user_exception
    return self.handle_http_exception(e)
  File "D:\microblog\venv\lib\site-packages\flask\app.py", line 730, in handle_http_exception
    return self.ensure_sync(handler)(e)  # type: ignore[no-any-return]
  File "D:\microblog\app\errors.py", line 6, in not_found_error
    return render_template('404.html'),404
  File "D:\microblog\venv\lib\site-packages\flask\templating.py", line 149, in render_template
    template = app.jinja_env.get_or_select_template(template_name_or_list)
  File "D:\microblog\venv\lib\site-packages\jinja2\environment.py", line 1081, in get_or_select_template
    return self.get_template(template_name_or_list, parent, globals)
  File "D:\microblog\venv\lib\site-packages\jinja2\environment.py", line 1010, in get_template
    return self._load_template(name, globals)
  File "D:\microblog\venv\lib\site-packages\jinja2\environment.py", line 969, in _load_template
    template = self.loader.load(self, name, self.make_globals(globals))
  File "D:\microblog\venv\lib\site-packages\jinja2\loaders.py", line 137, in load
    code = environment.compile(source, name, filename)
  File "D:\microblog\venv\lib\site-packages\jinja2\environment.py", line 768, in compile
    self.handle_exception(source=source_hint)
  File "D:\microblog\venv\lib\site-packages\jinja2\environment.py", line 936, in handle_exception
    raise rewrite_traceback_stack(source=source)
  File "D:\microblog\app\templates\404.html", line 4, in template
    <h1>{{_(Not Found)}}</h1>
jinja2.exceptions.TemplateSyntaxError: expected token ',', got 'Found'
