2024-04-13 10:36:11,570 ERROR: Exception on /user/vadiraj [GET] [in D:\microblog\venv\lib\site-packages\flask\app.py:828]
Traceback (most recent call last):
  File "D:\microblog\venv\lib\site-packages\flask\app.py", line 870, in full_dispatch_request
    rv = self.dispatch_request()
  File "D:\microblog\venv\lib\site-packages\flask\app.py", line 855, in dispatch_request
    return self.ensure_sync(self.view_functions[rule.endpoint])(**view_args)  # type: ignore[no-any-return]
  File "D:\microblog\venv\lib\site-packages\flask_login\utils.py", line 290, in decorated_view
    return current_app.ensure_sync(func)(*args, **kwargs)
  File "D:\microblog\app\routes.py", line 72, in user
    user = User.query.filter_by(username=username).first_or_404()
  File "D:\microblog\venv\lib\site-packages\flask_sqlalchemy\query.py", line 46, in first_or_404
    abort(404, description=description)
  File "D:\microblog\venv\lib\site-packages\flask\helpers.py", line 272, in abort
    current_app.aborter(code, *args, **kwargs)
  File "D:\microblog\venv\lib\site-packages\werkzeug\exceptions.py", line 861, in __call__
    raise self.mapping[code](*args, **kwargs)
werkzeug.exceptions.NotFound: 404 Not Found: The requested URL was not found on the server. If you entered the URL manually please check your spelling and try again.

During handling of the above exception, another exception occurred:

Traceback (most recent call last):
  File "D:\microblog\venv\lib\site-packages\flask\app.py", line 1463, in wsgi_app
    response = self.full_dispatch_request()
  File "D:\microblog\venv\lib\site-packages\flask\app.py", line 872, in full_dispatch_request
    rv = self.handle_user_exception(e)
  File "D:\microblog\venv\lib\site-packages\flask\app.py", line 755, in handle_user_exception
    return self.handle_http_exception(e)
  File "D:\microblog\venv\lib\site-packages\flask\app.py", line 730, in handle_http_exception
    return self.ensure_sync(handler)(e)  # type: ignore[no-any-return]
  File "D:\microblog\app\errors.py", line 6, in not_found_error
    return render_template('404.html'),404
  File "D:\microblog\venv\lib\site-packages\flask\templating.py", line 149, in render_template
    template = app.jinja_env.get_or_select_template(template_name_or_list)
  File "D:\microblog\venv\lib\site-packages\jinja2\environment.py", line 1081, in get_or_select_template
    return self.get_template(template_name_or_list, parent, globals)
  File "D:\microblog\venv\lib\site-packages\jinja2\environment.py", line 1010, in get_template
    return self._load_template(name, globals)
  File "D:\microblog\venv\lib\site-packages\jinja2\environment.py", line 969, in _load_template
    template = self.loader.load(self, name, self.make_globals(globals))
  File "D:\microblog\venv\lib\site-packages\jinja2\loaders.py", line 137, in load
    code = environment.compile(source, name, filename)
  File "D:\microblog\venv\lib\site-packages\jinja2\environment.py", line 768, in compile
    self.handle_exception(source=source_hint)
  File "D:\microblog\venv\lib\site-packages\jinja2\environment.py", line 936, in handle_exception
    raise rewrite_traceback_stack(source=source)
  File "D:\microblog\app\templates\404.html", line 4, in template
    <h1>{{_(Not Found)}}</h1>
jinja2.exceptions.TemplateSyntaxError: expected token ',', got 'Found'
2024-04-13 10:36:36,719 INFO: Microblog startup [in D:\microblog\app\__init__.py:54]
2024-04-13 10:36:39,026 ERROR: Exception on /user/vadiraj [GET] [in D:\microblog\venv\lib\site-packages\flask\app.py:828]
Traceback (most recent call last):
  File "D:\microblog\venv\lib\site-packages\flask\app.py", line 870, in full_dispatch_request
    rv = self.dispatch_request()
  File "D:\microblog\venv\lib\site-packages\flask\app.py", line 855, in dispatch_request
    return self.ensure_sync(self.view_functions[rule.endpoint])(**view_args)  # type: ignore[no-any-return]
  File "D:\microblog\venv\lib\site-packages\flask_login\utils.py", line 290, in decorated_view
    return current_app.ensure_sync(func)(*args, **kwargs)
  File "D:\microblog\app\routes.py", line 72, in user
    user = User.query.filter_by(username=username).first_or_404()
  File "D:\microblog\venv\lib\site-packages\flask_sqlalchemy\query.py", line 46, in first_or_404
    abort(404, description=description)
  File "D:\microblog\venv\lib\site-packages\flask\helpers.py", line 272, in abort
    current_app.aborter(code, *args, **kwargs)
  File "D:\microblog\venv\lib\site-packages\werkzeug\exceptions.py", line 861, in __call__
    raise self.mapping[code](*args, **kwargs)
werkzeug.exceptions.NotFound: 404 Not Found: The requested URL was not found on the server. If you entered the URL manually please check your spelling and try again.

During handling of the above exception, another exception occurred:

Traceback (most recent call last):
  File "D:\microblog\venv\lib\site-packages\flask\app.py", line 1463, in wsgi_app
    response = self.full_dispatch_request()
  File "D:\microblog\venv\lib\site-packages\flask\app.py", line 872, in full_dispatch_request
    rv = self.handle_user_exception(e)
  File "D:\microblog\venv\lib\site-packages\flask\app.py", line 755, in handle_user_exception
    return self.handle_http_exception(e)
  File "D:\microblog\venv\lib\site-packages\flask\app.py", line 730, in handle_http_exception
    return self.ensure_sync(handler)(e)  # type: ignore[no-any-return]
  File "D:\microblog\app\errors.py", line 6, in not_found_error
    return render_template('404.html'),404
  File "D:\microblog\venv\lib\site-packages\flask\templating.py", line 149, in render_template
    template = app.jinja_env.get_or_select_template(template_name_or_list)
  File "D:\microblog\venv\lib\site-packages\jinja2\environment.py", line 1081, in get_or_select_template
    return self.get_template(template_name_or_list, parent, globals)
  File "D:\microblog\venv\lib\site-packages\jinja2\environment.py", line 1010, in get_template
    return self._load_template(name, globals)
  File "D:\microblog\venv\lib\site-packages\jinja2\environment.py", line 969, in _load_template
    template = self.loader.load(self, name, self.make_globals(globals))
  File "D:\microblog\venv\lib\site-packages\jinja2\loaders.py", line 137, in load
    code = environment.compile(source, name, filename)
  File "D:\microblog\venv\lib\site-packages\jinja2\environment.py", line 768, in compile
    self.handle_exception(source=source_hint)
  File "D:\microblog\venv\lib\site-packages\jinja2\environment.py", line 936, in handle_exception
    raise rewrite_traceback_stack(source=source)
  File "D:\microblog\app\templates\404.html", line 4, in template
    <h1>{{_(Not Found)}}</h1>
jinja2.exceptions.TemplateSyntaxError: expected token ',', got 'Found'
2024-04-13 10:37:15,759 INFO: Microblog startup [in D:\microblog\app\__init__.py:54]
2024-04-13 11:58:49,485 INFO: Microblog startup [in D:\microblog\app\__init__.py:54]
2024-04-13 11:59:43,383 INFO: Microblog startup [in D:\microblog\app\__init__.py:54]
2024-04-13 12:00:38,683 INFO: Microblog startup [in D:\microblog\app\__init__.py:54]
2024-04-13 12:23:52,749 INFO: Microblog startup [in D:\microblog\app\__init__.py:54]
2024-04-13 12:24:04,213 INFO: Microblog startup [in D:\microblog\app\__init__.py:54]
2024-04-13 12:24:08,448 INFO: Microblog startup [in D:\microblog\app\__init__.py:54]
2024-04-13 12:24:15,638 INFO: Microblog startup [in D:\microblog\app\__init__.py:54]
2024-04-13 12:24:22,944 ERROR: Exception on /index [GET] [in D:\microblog\venv\lib\site-packages\flask\app.py:828]
Traceback (most recent call last):
  File "D:\microblog\venv\lib\site-packages\flask\app.py", line 1463, in wsgi_app
    response = self.full_dispatch_request()
  File "D:\microblog\venv\lib\site-packages\flask\app.py", line 872, in full_dispatch_request
    rv = self.handle_user_exception(e)
  File "D:\microblog\venv\lib\site-packages\flask\app.py", line 870, in full_dispatch_request
    rv = self.dispatch_request()
  File "D:\microblog\venv\lib\site-packages\flask\app.py", line 855, in dispatch_request
    return self.ensure_sync(self.view_functions[rule.endpoint])(**view_args)  # type: ignore[no-any-return]
  File "D:\microblog\venv\lib\site-packages\flask_login\utils.py", line 290, in decorated_view
    return current_app.ensure_sync(func)(*args, **kwargs)
  File "D:\microblog\app\routes.py", line 31, in index
    return render_template('index.html',title='home',posts=posts.items,form=form,next_url=next_url,prev_url=prev_url)
  File "D:\microblog\venv\lib\site-packages\flask\templating.py", line 150, in render_template
    return _render(app, template, context)
  File "D:\microblog\venv\lib\site-packages\flask\templating.py", line 131, in _render
    rv = template.render(context)
  File "D:\microblog\venv\lib\site-packages\jinja2\environment.py", line 1301, in render
    self.environment.handle_exception()
  File "D:\microblog\venv\lib\site-packages\jinja2\environment.py", line 936, in handle_exception
    raise rewrite_traceback_stack(source=source)
  File "D:\microblog\app\templates\index.html", line 1, in top-level template code
    {% extends "base.html" %}
  File "D:\microblog\venv\lib\site-packages\jinja2\environment.py", line 936, in handle_exception
    raise rewrite_traceback_stack(source=source)
  File "D:\microblog\app\templates\base.html", line 69, in template
    $(destLang).html('<img src="{{url_for(\'static\',filaname=\'loading.gif\')}}">')
jinja2.exceptions.TemplateSyntaxError: unexpected char '\\' at 2836
2024-04-13 12:25:37,546 INFO: Microblog startup [in D:\microblog\app\__init__.py:54]
2024-04-13 23:17:24,166 INFO: Microblog startup [in D:\microblog\app\__init__.py:65]
